Workbook

Sheet Summary
B2: THE ARCHIVE — Ambient Intelligence
B3: Purchase Order & Bill of Materials
B4: Project Code: ARC-2026-AI
B5: Date: 2026-03-14
B6: Version: April 2026
B7: Configuration: 8 Display Panels + 1 Control Surface
B9: Category | C9: Items | D9: Subtotal
B10: Acrylic & Laser Cutting | D10: ='BOM - Acrylic'!H15
B11: Electronics | D11: ='BOM - Electronics'!H23
B12: Hardware & Fasteners | D12: ='BOM - Hardware'!H14
B13: Cabling & Power | D13: ='BOM - Cabling'!H15
B14: Consumables & Tools | D14: ='BOM - Consumables'!H13
B15: SUBTOTAL (Materials) | D15: =SUM(D10:D14)
B16: Estimated Shipping (10%) | D16: =D15*0.10
B17: Estimated Tax (8.5%) | D17: =D15*0.085
B18: Contingency (10%) | D18: =D15*0.10
B19: GRAND TOTAL | D19: =SUM(D15:D18)
B21: Notes:
B22: 1. All prices are estimates based on typical US retail/online pricing as of March 2026.
B23: 2. Quantities include 8 display panels + 1 control surface unless noted.
B24: 3. ESP32 DevKit selected for built-in WiFi; optional W5500 Ethernet modules listed separately.
B25: 4. Noctua fans are optional per-panel; included for all 8 panels in this estimate.
B26: 5. Laser cutting priced at typical makerspace / online service rates.
B27: 6. Acrylic sourced as cut-to-size sheets; bulk sheet pricing may reduce cost.

Sheet BOM - Acrylic
A1: Item # | B1: Part Description | C1: Material / Spec | D1: Qty/Panel | E1: Total Qty | F1: Unit Price | G1: Ext. Price | H1: Supplier | I1: Notes
A2: 1 | B2: Backplate Panel | C2: Smoked 3mm acrylic, 12"×16" (304.8×406.4mm) | D2: 1/panel | E2: 8 | F2: 12 | G2: =E2*F2 | H2: TAP Plastics | I2: Laser etch: grid, topo, specimen ID
A3: 2 | B3: Mounting Layer Panel | C3: Clear 3mm acrylic, 12"×16" (304.8×406.4mm) | D3: 1/panel | E3: 8 | F3: 8 | G3: =E3*F3 | H3: TAP Plastics | I3: Custom device cutouts per artist
A4: 3 | B4: Info Strip | C4: Black 3mm acrylic, 12"×2" (304.8×50mm) | D4: 1/panel | E4: 8 | F4: 4 | G4: =E4*F4 | H4: TAP Plastics | I4: OLED window + metadata etching
A5: 4 | B5: Edge-Lit Accent Strip | C5: Fluorescent 3mm acrylic, assorted colors, 12"×0.5" | D5: 1/panel | E5: 8 | F5: 6 | G5: =E5*F5 | H5: Canal Plastics | I5: Unique color per artist (green/orange/cyan)
A6: 5 | B6: Control Surface Panel | C6: Smoked 3mm acrylic, 280×170mm (11"×6.7") | D6: 1 total | E6: 1 | F6: 8 | G6: =E6*F6 | H6: TAP Plastics | I6: 4× pot cutouts, RF spectrum etch
A7: 6 | B7: Control Surface Edge Strip | C7: Cyan fluorescent 3mm acrylic, 280×10mm | D7: 1 total | E7: 1 | F7: 3 | G7: =E7*F7 | H7: Canal Plastics | I7: Edge-lit accent for control panel
A8: 7 | B8: Fan Bracket | C8: Clear 3mm acrylic, 80×55mm | D8: 1/panel | E8: 8 | F8: 2 | G8: =E8*F8 | H8: TAP Plastics | I8: 40mm Noctua fan mount
A9: 8 | B9: Laser Cutting Service | C9: Cut + etch all layers: 24 panel layers + 1 control + 8 fan brackets = 33 pcs | D9: — | E9: 33 | F9: 15 | G9: =E9*F9 | H9: SendCutSend / Local | I9: 3-color layer separation (cut/deep/light etch)
A10: 9 | B10: Spare Acrylic Allowance | C10: 15% waste/breakage buffer on all acrylic | D10: — | E10: 1 | F10: 15 | G10: =E10*F10 | H10: — | I10: Covers breakage during laser/assembly
A11: SUBTOTAL | G11: =SUM(G2:G10)

Sheet BOM - Electronics
A1: Item # | B1: Part Description | C1: Material / Spec | D1: Qty/Panel | E1: Total Qty | F1: Unit Price | G1: Ext. Price | H1: Supplier | I1: Notes
A2: OLED DISPLAYS
A3: 1 | B3: OLED Display Module | C3: 0.96" 128×64 I2C SSD1306, white or blue | D3: 1/panel | E3: 8 | F3: 4 | G3: =E3*F3 | H3: Amazon / AliExpress | I3: I2C addr 0x3C; drives via ESP32
A4: 2 | B4: OLED Connector Cable | C4: 4-pin JST-XH pre-crimped, 150mm | D4: 1/panel | E4: 10 | F4: 0.5 | G4: =E4*F4 | H4: Amazon | I4: 2 spares; VCC/GND/SDA/SCL
A5: MICROCONTROLLERS
A6: 3 | B6: ESP32 DevKit V1 | C6: ESP-WROOM-32, WiFi+BT, USB-C, 38-pin | D6: 1/panel | E6: 9 | F6: 6 | G6: =E6*F6 | H6: Amazon / AliExpress | I6: 8 panels + 1 control surface
A7: 4 | B7: ESP32 Ethernet Module (W5500) | C7: W5500 SPI Ethernet adapter for ESP32 | D7: 1/panel | E7: 9 | F7: 4 | G7: =E7*F7 | H7: Amazon / AliExpress | I7: Optional: for wired Maestra connection
A8: NETWORKING
A9: 5 | B9: Ethernet Cable Cat6 | C9: 3ft (1m) patch cable, black | D9: 1/panel | E9: 9 | F9: 2 | G9: =E9*F9 | H9: Amazon | I9: If using wired Ethernet
A10: 6 | B10: Ethernet Switch | C10: 16-port unmanaged gigabit (TP-Link TL-SG116) | D10: 1 total | E10: 1 | F10: 45 | G10: =E10*F10 | H10: Amazon | I10: All panels + Maestra + spare ports
A11: 7 | B11: WiFi Access Point | C11: Dedicated 2.4GHz AP for panel mesh (optional) | D11: 1 total | E11: 1 | F11: 40 | G11: =E11*F11 | H11: Amazon | I11: Alt to Ethernet; dedicated SSID for panels
A12: CONTROL SURFACE
A13: 8 | B13: Rotary Potentiometer 10kΩ | C13: B10K linear taper, 16mm panel mount, 6mm shaft | D13: 4/ctrl | E13: 4 | F13: 2 | G13: =E13*F13 | H13: Mouser / DigiKey | I13: Freq/Gain/Drift/Blend controls
A14: 9 | B14: Potentiometer Knobs | C14: Aluminum knurled, black, 6mm D-shaft | D14: 4/ctrl | E14: 4 | F14: 3 | G14: =E14*F14 | H14: Amazon / Mouser | I14: Tactile feel, industrial aesthetic
A15: 10 | B15: Anti-Rotation Washer | C15: Tab washer for 16mm pot, prevents spin | D15: 4/ctrl | E15: 4 | F15: 0.25 | G15: =E15*F15 | H15: Mouser | I15: Matches control surface anti-rotation tabs
A16: POWER
A17: 11 | B17: 5V 10A Power Supply | C17: Mean Well LRS-50-5 or equiv, 50W | D17: 1 total | E17: 1 | F17: 18 | G17: =E17*F17 | H17: Mouser / Amazon | I17: Central PSU for all panels
A18: 12 | B18: Power Distribution Board | C18: 5V DC bus bar / screw terminal strip, 10-pos | D18: 1 total | E18: 1 | F18: 12 | G18: =E18*F18 | H18: Amazon | I18: Fan-out 5V to all panels
A19: 13 | B19: DC Barrel Jack Breakout | C19: 5.5×2.1mm to screw terminal | D19: 1/panel | E19: 9 | F19: 1 | G19: =E19*F19 | H19: Amazon | I19: Per-panel power input
A20: PASSIVE COMPONENTS
A21: 14 | B21: 10kΩ Resistors (pack) | C21: 1/4W, 5%, carbon film, 100-pack | D21: 1 pack | E21: 1 | F21: 3 | G21: =E21*F21 | H21: Mouser / Amazon | I21: I2C pull-ups, voltage dividers
A22: 15 | B22: 4.7kΩ Resistors (pack) | C22: 1/4W, 5%, carbon film, 100-pack | D22: 1 pack | E22: 1 | F22: 3 | G22: =E22*F22 | H22: Mouser | I22: I2C pull-ups (SDA/SCL)
A23: 16 | B23: 0.1µF Ceramic Capacitors | C23: MLCC, 50V, pack of 50 | D23: 1 pack | E23: 1 | F23: 3 | G23: =E23*F23 | H23: Mouser / DigiKey | I23: Decoupling per MCU
A24: 17 | B24: 100µF Electrolytic Caps | C24: 25V, radial, low ESR | D24: 1/panel | E24: 10 | F24: 0.5 | G24: =E24*F24 | H24: Mouser | I24: Bulk power filtering per panel
A25: 18 | B25: Prototype Perfboard | C25: 5×7cm, double-sided, FR4 | D25: 1/panel | E25: 10 | F25: 1 | G25: =E25*F25 | H25: Amazon | I25: Custom breakout/adapter boards
A26: THERMAL
A27: 19 | B27: 40mm Noctua Fan | C27: NF-A4x10 5V, 4-pin PWM, 17.9 dBA | D27: 1/panel | E27: 8 | F27: 14 | G27: =E27*F27 | H27: Amazon / Noctua | I27: Ultra-quiet; mounts in fan bracket
A28: SUBTOTAL | G28: =SUM(G2:G27)

Sheet BOM - Hardware
A1: Item # | B1: Part Description | C1: Material / Spec | D1: Qty/Panel | E1: Total Qty | F1: Unit Price | G1: Ext. Price | H1: Supplier | I1: Notes
A2: 1 | B2: M3×15mm Brass Standoffs | C2: Hex, male-female, brass | D2: 12/panel | E2: 100 | F2: 0.25 | G2: =E2*F2 | H2: McMaster-Carr | I2: Panel layer spacing (15-20mm gap)
A3: 2 | B3: M3×6mm Socket Head Screws | C3: Stainless steel, Allen key | D3: 12/panel | E3: 110 | F3: 0.1 | G3: =E3*F3 | H3: McMaster-Carr | I3: Standoff attachment through acrylic
A4: 3 | B4: M3 Hex Nuts | C4: Stainless steel | D4: 12/panel | E4: 100 | F4: 0.05 | G4: =E4*F4 | H4: McMaster-Carr | I4: Standoff locking
A5: 4 | B5: M3 Nylon Washers | C5: Clear nylon, prevents acrylic cracking | D5: 24/panel | E5: 200 | F5: 0.03 | G5: =E5*F5 | H5: McMaster-Carr | I5: Both sides of each acrylic hole
A6: 5 | B6: M4×20mm Socket Head Screws | C6: Stainless steel | D6: 6/panel | E6: 55 | F6: 0.15 | G6: =E6*F6 | H6: McMaster-Carr | I6: French cleat wall mounting
A7: 6 | B7: M4 Hex Nuts | C7: Stainless steel | D7: 6/panel | E7: 55 | F7: 0.08 | G7: =E7*F7 | H7: McMaster-Carr | I7: Wall mount fastening
A8: 7 | B8: M4 Nylon Washers | C8: Clear nylon | D8: 6/panel | E8: 55 | F8: 0.05 | G8: =E8*F8 | H8: McMaster-Carr | I8: Acrylic protection at mount points
A9: 8 | B9: M3×8mm Screws (Fan Mount) | C9: Stainless steel, pan head | D9: 4/bracket | E9: 40 | F9: 0.1 | G9: =E9*F9 | H9: McMaster-Carr | I9: Fan to bracket attachment
A10: 9 | B10: M3×12mm Screws (Bracket) | C10: Stainless steel, pan head | D10: 4/bracket | E10: 40 | F10: 0.1 | G10: =E10*F10 | H10: McMaster-Carr | I10: Bracket to panel attachment
A11: 10 | B11: French Cleat Rail (12") | C11: Aluminum, interlocking Z-profile | D11: 1/panel | E11: 8 | F11: 5 | G11: =E11*F11 | H11: Amazon | I11: Wall-side + panel-side pair
A12: 11 | B12: Wall Anchors + Screws | C12: Heavy-duty drywall anchors, #10 | D12: 2/panel | E12: 16 | F12: 0.5 | G12: =E12*F12 | H12: Amazon | I12: For French cleat wall mounting
A13: SUBTOTAL | G13: =SUM(G2:G12)

Sheet BOM - Cabling
A1: Item # | B1: Part Description | C1: Material / Spec | D1: Qty/Panel | E1: Total Qty | F1: Unit Price | G1: Ext. Price | H1: Supplier | I1: Notes
A2: 1 | B2: USB-C Cable (6ft) | C2: USB-A to USB-C, data+power, braided | D2: 1/panel | E2: 9 | F2: 4 | G2: =E2*F2 | H2: Amazon | I2: ESP32 programming & power
A3: 2 | B3: Silicone Hook-up Wire Set | C3: 22AWG, 6 colors × 25ft spools | D3: 1 set | E3: 1 | F3: 15 | G3: =E3*F3 | H3: Amazon | I3: Internal panel wiring (I2C, power, signal)
A4: 3 | B4: Dupont Jumper Wire Set | C4: M-F, F-F, M-M, 40-pin ribbon, 20cm | D4: 1 pack | E4: 3 | F4: 4 | G4: =E4*F4 | H4: Amazon | I4: Prototyping & ESP32 connections
A5: 4 | B5: 4-pin JST-XH Connector Pairs | C5: Pre-crimped leads, 2.54mm pitch | D5: 1/panel | E5: 10 | F5: 0.5 | G5: =E5*F5 | H5: Amazon | I5: OLED I2C detachable connection
A6: 5 | B6: 2-pin JST-XH Connector Pairs | C6: Pre-crimped leads, 2.54mm pitch | D6: 2/panel | E6: 20 | F6: 0.25 | G6: =E6*F6 | H6: Amazon | I6: Power connections (fan, OLED, etc.)
A7: 6 | B7: Braided Cable Sleeve (50ft) | C7: 6mm matte black PET expandable | D7: — | E7: 1 | F7: 12 | G7: =E7*F7 | H7: Amazon | I7: Per design spec: matte black mesh
A8: 7 | B8: Heat Shrink Tubing Kit | C8: Assorted dia, black, 2:1 ratio | D8: — | E8: 1 | F8: 6 | G8: =E8*F8 | H8: Amazon | I8: Cable termination and labeling
A9: 8 | B9: Heat Shrink Label Tape | C9: White on black, 6mm, monospace print | D9: — | E9: 1 | F9: 8 | G9: =E9*F9 | H9: Amazon | I9: Monospace font cable ID labels
A10: 9 | B10: 18AWG Silicone Wire (Red) | C10: 25ft spool, high-strand silicone | D10: — | E10: 1 | F10: 5 | G10: =E10*F10 | H10: Amazon | I10: 5V power distribution trunk
A11: 10 | B11: 18AWG Silicone Wire (Black) | C11: 25ft spool, high-strand silicone | D11: — | E11: 1 | F11: 5 | G11: =E11*F11 | H11: Amazon | I11: GND power distribution trunk
A12: 11 | B12: Cable Ties (100-pack) | C12: 4" black nylon, releasable preferred | D12: — | E12: 1 | F12: 3 | G12: =E12*F12 | H12: Amazon | I12: Internal cable management
A13: 12 | B13: Adhesive Cable Clips (50-pack) | C13: Black, self-adhesive, 6mm | D13: — | E13: 1 | F13: 5 | G13: =E13*F13 | H13: Amazon | I13: Wall/panel cable routing
A14: 13 | B14: IEC Power Cable | C14: C14 to C13, 6ft, for Mean Well PSU | D14: 1 total | E14: 1 | F14: 5 | G14: =E14*F14 | H14: Amazon | I14: Wall outlet to central PSU
A15: SUBTOTAL | G15: =SUM(G2:G14)

Sheet BOM - Consumables
A1: Item # | B1: Part Description | C1: Material / Spec | D1: Qty/Panel | E1: Total Qty | F1: Unit Price | G1: Ext. Price | H1: Supplier | I1: Notes
A2: 1 | B2: Acrylic Cement (Weld-On #4) | C2: Water-thin solvent cement, 4oz | D2: — | E2: 1 | F2: 8 | G2: =E2*F2 | H2: TAP Plastics | I2: Info strip bonding to panel
A3: 2 | B3: Isopropyl Alcohol 99% | C3: 16oz bottle | D3: — | E3: 1 | F3: 5 | G3: =E3*F3 | H3: Amazon | I3: Acrylic cleaning before assembly
A4: 3 | B4: Microfiber Cloths (10-pack) | C4: Lint-free, soft | D4: — | E4: 1 | F4: 6 | G4: =E4*F4 | H4: Amazon | I4: Acrylic polishing & cleaning
A5: 4 | B5: Solder Wire | C5: 60/40 rosin core, 0.8mm, 100g | D5: — | E5: 1 | F5: 8 | G5: =E5*F5 | H5: Amazon | I5: Electronics assembly
A6: 5 | B6: Flux Pen | C6: No-clean liquid flux | D6: — | E6: 1 | F6: 5 | G6: =E6*F6 | H6: Amazon | I6: Improved solder flow
A7: 6 | B7: Kapton Tape | C7: 12mm × 30m, polyimide | D7: — | E7: 1 | F7: 6 | G7: =E7*F7 | H7: Amazon | I7: Heat protection & insulation
A8: 7 | B8: 3M VHB Double-Sided Tape | C8: 12mm × 5m, clear, heavy duty | D8: — | E8: 1 | F8: 8 | G8: =E8*F8 | H8: Amazon | I8: OLED & ESP32 mounting to acrylic
A9: 8 | B9: Anti-Static Wrist Strap | C9: Adjustable, grounding clip | D9: — | E9: 1 | F9: 5 | G9: =E9*F9 | H9: Amazon | I9: ESD protection during assembly
A10: 9 | B10: Nylon Standoff Kit (M2/M2.5/M3) | C10: Assorted lengths, 300-piece kit | D10: — | E10: 1 | F10: 10 | G10: =E10*F10 | H10: Amazon | I10: PCB & OLED board mounting
A11: 10 | B11: Loctite Blue 242 | C11: Threadlocker, medium strength, 6ml | D11: — | E11: 1 | F11: 6 | G11: =E11*F11 | H11: Amazon | I11: Prevent vibration loosening
A12: SUBTOTAL | G12: =SUM(G2:G11)

Sheet Purchase Order
B2: PURCHASE ORDER
B4: PO Number: | C4: PO-ARC-2026-001
B5: Date: | C5: 2026-03-14
B6: Project: | C6: THE ARCHIVE — Ambient Intelligence (ARC-2026-AI)
B7: Ship To: | C7: [Installation Venue Address]
B8: Prepared By: | C8: Jordan Snyder
A10: Line | B10: Vendor | C10: Item Description | D10: Part #/SKU | E10: Qty | F10: Unit Price | G10: Ext. Price | H10: Lead Time | I10: Status
A11: TAP PLASTICS / CANAL PLASTICS
A12: 1 | B12: TAP Plastics | C12: Smoked 3mm acrylic sheets 12"×16" (×8) | D12: — | E12: 8 | F12: 12 | G12: =E12*F12 | H12: 3-5 days | I12: Not Ordered
A13: 2 | B13: TAP Plastics | C13: Clear 3mm acrylic sheets 12"×16" (×8) | D13: — | E13: 8 | F13: 8 | G13: =E13*F13 | H13: 3-5 days | I13: Not Ordered
A14: 3 | B14: TAP Plastics | C14: Black 3mm acrylic strips 12"×2" (×8) | D14: — | E14: 8 | F14: 4 | G14: =E14*F14 | H14: 3-5 days | I14: Not Ordered
A15: 4 | B15: Canal Plastics | C15: Fluorescent acrylic strips, assorted colors (×8) | D15: — | E15: 8 | F15: 6 | G15: =E15*F15 | H15: 5-7 days | I15: Not Ordered
A16: 5 | B16: TAP Plastics | C16: Control surface + fan bracket acrylic pieces | D16: — | E16: 10 | F16: 3 | G16: =E16*F16 | H16: 3-5 days | I16: Not Ordered
A17: 6 | B17: SendCutSend | C17: Laser cutting service (33 pieces, cut + etch) | D17: Custom | E17: 33 | F17: 15 | G17: =E17*F17 | H17: 7-10 days | I17: Not Ordered
F18: Subtotal: | G18: =SUM(G12:G17)
A19: AMAZON / ADAFRUIT / NOCTUA
A20: 7 | B20: Amazon | C20: ESP32 DevKit V1 (WiFi+BT) × 9 | D20: ESP-WROOM-32 | E20: 9 | F20: 6 | G20: =E20*F20 | H20: 2-3 days | I20: Not Ordered
A21: 8 | B21: Amazon | C21: 0.96" OLED SSD1306 I2C modules × 8 | D21: SSD1306 | E21: 8 | F21: 4 | G21: =E21*F21 | H21: 2-3 days | I21: Not Ordered
A22: 9 | B22: Amazon | C22: W5500 Ethernet modules × 9 (optional) | D22: W5500-SPI | E22: 9 | F22: 4 | G22: =E22*F22 | H22: 2-5 days | I22: Not Ordered
A23: 10 | B23: Amazon | C23: 16-port Gigabit Ethernet Switch | D23: TL-SG116 | E23: 1 | F23: 45 | G23: =E23*F23 | H23: 2-3 days | I23: Not Ordered
A24: 11 | B24: Amazon | C24: Cat6 Ethernet Cables 3ft, black × 9 | D24: — | E24: 9 | F24: 2 | G24: =E24*F24 | H24: 2-3 days | I24: Not Ordered
A25: 12 | B25: Amazon | C25: Noctua NF-A4x10 5V 40mm fans × 8 | D25: NF-A4x10-5V | E25: 8 | F25: 14 | G25: =E25*F25 | H25: 2-3 days | I25: Not Ordered
A26: 13 | B26: Amazon | C26: Mean Well 5V 10A PSU | D26: LRS-50-5 | E26: 1 | F26: 18 | G26: =E26*F26 | H26: 2-3 days | I26: Not Ordered
A27: 14 | B27: Amazon | C27: Power distribution board + barrel jacks | D27: — | E27: 1 | F27: 21 | G27: =E27*F27 | H27: 2-3 days | I27: Not Ordered
A28: 15 | B28: Amazon | C28: USB-C cables, jumper wires, cable mgmt bundle | D28: — | E28: 1 | F28: 80 | G28: =E28*F28 | H28: 2-3 days | I28: Not Ordered
A29: 16 | B29: Amazon | C29: Consumables bundle (solder, tape, IPA, cloths, etc.) | D29: — | E29: 1 | F29: 67 | G29: =E29*F29 | H29: 2-3 days | I29: Not Ordered
F30: Subtotal: | G30: =SUM(G20:G29)
A31: MCMASTER-CARR / BOLT DEPOT
A32: 17 | B32: McMaster-Carr | C32: M3 Brass Standoffs 15mm × 100 | D32: 91780A | E32: 100 | F32: 0.25 | G32: =E32*F32 | H32: 1-2 days | I32: Not Ordered
A33: 18 | B33: McMaster-Carr | C33: M3 Socket Head Screws 6mm × 110 | D33: 91292A | E33: 110 | F33: 0.1 | G33: =E33*F33 | H33: 1-2 days | I33: Not Ordered
A34: 19 | B34: McMaster-Carr | C34: M3 Nuts × 100 + M3 Nylon Washers × 200 | D34: Various | E34: 300 | F34: 0.04 | G34: =E34*F34 | H34: 1-2 days | I34: Not Ordered
A35: 20 | B35: McMaster-Carr | C35: M4 Screws 20mm × 55 + M4 Nuts × 55 + Washers × 55 | D35: Various | E35: 165 | F35: 0.1 | G35: =E35*F35 | H35: 1-2 days | I35: Not Ordered
A36: 21 | B36: McMaster-Carr | C36: M3 Fan/bracket screws (8mm + 12mm) × 80 | D36: Various | E36: 80 | F36: 0.1 | G36: =E36*F36 | H36: 1-2 days | I36: Not Ordered
A37: 22 | B37: Amazon | C37: French Cleat Rails 12" × 8 + Wall Anchors × 16 | D37: — | E37: 8 | F37: 6 | G37: =E37*F37 | H37: 2-3 days | I37: Not Ordered
F38: Subtotal: | G38: =SUM(G32:G37)
A39: MOUSER / DIGIKEY
A40: 23 | B40: Mouser | C40: B10K Potentiometers 16mm × 4 | D40: P160KN-B10K | E40: 4 | F40: 2 | G40: =E40*F40 | H40: 3-5 days | I40: Not Ordered
A41: 24 | B41: Mouser | C41: Aluminum Pot Knobs × 4 + Anti-rotation washers × 4 | D41: — | E41: 4 | F41: 3.25 | G41: =E41*F41 | H41: 3-5 days | I41: Not Ordered
A42: 25 | B42: Mouser | C42: Resistor packs (10kΩ + 4.7kΩ) × 2 | D42: — | E42: 2 | F42: 3 | G42: =E42*F42 | H42: 3-5 days | I42: Not Ordered
A43: 26 | B43: Mouser | C43: Capacitor packs (0.1µF×50 + 100µF×10) | D43: — | E43: 2 | F43: 4 | G43: =E43*F43 | H43: 3-5 days | I43: Not Ordered
...
